Workbook

Sheet Synthèse
B1: Analyse maintenance SAP PM
B2: Période du 01/09/2025 au 31/08/2026 · exemple_export_sap_pm.xlsx · généré le 29/10/2026 09:42
B4: Ordres analysés | D4: Pannes | F4: Heures d'arrêt | H4: Coût total (USD)
B5: =COUNTA('Données'!$A$2:$A$822) -> 821 | D5: =SUM('Équipements'!$D$5:$D$27) -> 202 | F5: =SUM('Équipements'!$E$5:$E$27) -> 975.96 | H5: =SUM('Données'!$O$2:$O$822) -> 1454326.7
B7: MTTR moyen | D7: Disponibilité moyenne | F7: Part de travail planifié | H7: Ordres ouverts
B8: =IFERROR(SUM('Équipements'!$E$5:$E$27)/COUNTIFS('Données'!$D$2:$D$822,1,'Données'!$N$2:$N$822,">0"),0) -> 6.7307586 | D8: =1-SUM('Équipements'!$E$5:$E$27)/('Équipements'!$D$2*COUNTA('Équipements'!$A$5:$A$27)) -> 0.99515605 | F8: =(COUNTIFS('Données'!$C$2:$C$822,"Inspection")+COUNTIFS('Données'!$C$2:$C$822,"Préventif"))/COUNTA('Données'!$A$2:$A$822) -> 0.75395859 | H8: =SUM('Données'!$Q$2:$Q$822) -> 74
B11: Résumé
B12: Analyse automatique (règles) — activez l'IA pour une analyse rédigée
B13: Sur 365 jours, 202 pannes ont causé 976 h d'arrêt sur 23 équipements (MTTR moyen 6.7 h). Les pertes sont concentrées : les 3 premiers équipements représentent 31% des arrêts. 9 pannes récurrentes ont été détectées, en priorité étanchéité / fuites sur Pompe à pulpe P-201.
B15: Constats clés
B16: • 3 équipements concentrent 31% des heures d'arrêt : Concasseur primaire giratoire (106 h), Pompe à pulpe P-201 (100 h), Broyeur à boulets n°1 (93 h).
B17: • Premier mode de défaillance : Étanchéité / Fuites (30 pannes, 15% du total).
B18: • Panne récurrente la plus marquée : Étanchéité / Fuites sur Pompe à pulpe P-201, 21 fois (intervalle moyen 15 jours).
B19: • Travail planifié (préventif + inspection) : 75% des ordres (référence courante : 80%).
B20: • 52 ordres ouverts sur 74 sont en retard (date de début de base dépassée), dont 14 au poste de travail MECA-01.
B22: Recommandations priorisées
B23: Priorité | C23: Équipement / périmètre | E23: Action recommandée | H23: Justification (données)
B24: Haute | C24: Concasseur primaire giratoire | E24: Lancer une analyse des causes racines (RCA) sur le mode « Bourrage / Obstruction ». | H24: 16 pannes, 106 h d'arrêt, MTTR 7.6 h, coût 168 319 $ sur la période.
B25: Haute | C25: Pompe à pulpe P-201 | E25: Lancer une analyse des causes racines (RCA) sur le mode « Étanchéité / Fuites ». | H25: 35 pannes, 100 h d'arrêt, MTTR 4.5 h, coût 88 832 $ sur la période.
B26: Haute | C26: Broyeur à boulets n°1 | E26: Lancer une analyse des causes racines (RCA) sur le mode « Lubrification ». | H26: 9 pannes, 93 h d'arrêt, MTTR 13.2 h, coût 206 840 $ sur la période.
B27: Haute | C27: Convoyeur à bande CV-03 | E27: Revoir le plan préventif pour « Bande / Convoyeur » : inspection tous les 18 jours environ, et vérifier la qualité des pièces / du montage. | H27: 12 occurrences, dont 7 à moins de 30 jours d'écart (intervalle moyen 31 j).
B28: Haute | C28: Crible vibrant SC-01 | E28: Revoir le plan préventif pour « Vibrations / Bruit » : inspection tous les 27 jours environ, et vérifier la qualité des pièces / du montage. | H28: 7 occurrences, dont 2 à moins de 30 jours d'écart (intervalle moyen 46 j).
B29: Haute | C29: Électrolyseur – redresseur RD-01 | E29: Revoir le plan préventif pour « Électrique » : inspection tous les 24 jours environ, et vérifier la qualité des pièces / du montage. | H29: 6 occurrences, dont 3 à moins de 30 jours d'écart (intervalle moyen 40 j).
B30: Moyenne | C30: Ensemble du site | E30: Augmenter la part de maintenance planifiée, en priorité sur les équipements critiques ci-dessus. | H30: 75% de travail planifié contre une référence de 80%.
B31: Moyenne | C31: Planification — postes MECA-01, MECA-MAN, MECA-HYD | E31: Revue hebdomadaire des ordres en retard par poste de travail : réaliser, replanifier ou clôturer (TECO). | H31: 52 ordres en retard, surtout : MECA-01 (14), MECA-MAN (11), MECA-HYD (7). 31 ordres sont ouverts depuis plus de 30 jours.
B32: Basse | C32: Saisie SAP | E32: Rendre le code dommage obligatoire à la clôture des avis de panne. | H32: 63% des pannes n'ont pas de code dommage : la classification repose sur le texte libre.
B34: Les recommandations sont des aides à la décision : elles doivent être validées par l'ingénieur maintenance avant toute action. Détails et définitions dans l'onglet « Méthode ».

Sheet Équipements
A1: Indicateurs par équipement
A2: Durée de la période analysée (h) : | D2: 8760 | E2: ← modifiable : MTBF et disponibilité se recalculent
A4: Équipement | B4: Désignation | C4: Poste technique | D4: Pannes | E4: Arrêt (h) | F4: MTTR (h) | G4: MTBF (h) | H4: Disponibilité | I4: Coût (USD) | J4: Ordres ouverts | K4: Mode principal | L4: Criticité (0-100)
A5: 10001001 | B5: Concasseur primaire giratoire | C5: KV-CON-010 | D5: =COUNTIFS('Données'!$E$2:$E$822,$A5,'Données'!$D$2:$D$822,1) -> 16 | E5: =SUMIFS('Données'!$N$2:$N$822,'Données'!$E$2:$E$822,$A5,'Données'!$D$2:$D$822,1) -> 105.9 | F5: =IFERROR(E5/COUNTIFS('Données'!$E$2:$E$822,$A5,'Données'!$D$2:$D$822,1,'Données'!$N$2:$N$822,">0"),"") -> 7.5642857 | G5: =IF(D5>0,('Équipements'!$D$2-E5)/D5,"") -> 540.88125 | H5: =MAX(0,'Équipements'!$D$2-E5)/'Équipements'!$D$2 -> 0.98791096 | I5: =SUMIFS('Données'!$O$2:$O$822,'Données'!$E$2:$E$822,$A5) -> 168318.99 | J5: =COUNTIFS('Données'!$E$2:$E$822,$A5,'Données'!$Q$2:$Q$822,1) -> 2 | K5: Bourrage / Obstruction | L5: 90
A6: 10001020 | B6: Pompe à pulpe P-201 | C6: KV-POM-201 | D6: =COUNTIFS('Données'!$E$2:$E$822,$A6,'Données'!$D$2:$D$822,1) -> 35 | E6: =SUMIFS('Données'!$N$2:$N$822,'Données'!$E$2:$E$822,$A6,'Données'!$D$2:$D$822,1) -> 99.7 | F6: =IFERROR(E6/COUNTIFS('Données'!$E$2:$E$822,$A6,'Données'!$D$2:$D$822,1,'Données'!$N$2:$N$822,">0"),"") -> 4.5318182 | G6: =IF(D6>0,('Équipements'!$D$2-E6)/D6,"") -> 247.43714 | H6: =MAX(0,'Équipements'!$D$2-E6)/'Équipements'!$D$2 -> 0.98861872 | I6: =SUMIFS('Données'!$O$2:$O$822,'Données'!$E$2:$E$822,$A6) -> 88831.6 | J6: =COUNTIFS('Données'!$E$2:$E$822,$A6,'Données'!$Q$2:$Q$822,1) -> 5 | K6: Étanchéité / Fuites | L6: 100
A7: 10001010 | B7: Broyeur à boulets n°1 | C7: KV-BRO-010 | D7: =COUNTIFS('Données'!$E$2:$E$822,$A7,'Données'!$D$2:$D$822,1) -> 9 | E7: =SUMIFS('Données'!$N$2:$N$822,'Données'!$E$2:$E$822,$A7,'Données'!$D$2:$D$822,1) -> 92.7 | F7: =IFERROR(E7/COUNTIFS('Données'!$E$2:$E$822,$A7,'Données'!$D$2:$D$822,1,'Données'!$N$2:$N$822,">0"),"") -> 13.242857 | G7: =IF(D7>0,('Équipements'!$D$2-E7)/D7,"") -> 963.03333 | H7: =MAX(0,'Équipements'!$D$2-E7)/'Équipements'!$D$2 -> 0.98941781 | I7: =SUMIFS('Données'!$O$2:$O$822,'Données'!$E$2:$E$822,$A7) -> 206839.56 | J7: =COUNTIFS('Données'!$E$2:$E$822,$A7,'Données'!$Q$2:$Q$822,1) -> 3 | K7: Lubrification | L7: 84
A8: 10001002 | B8: Concasseur secondaire à cône | C8: KV-CON-020 | D8: =COUNTIFS('Données'!$E$2:$E$822,$A8,'Données'!$D$2:$D$822,1) -> 14 | E8: =SUMIFS('Données'!$N$2:$N$822,'Données'!$E$2:$E$822,$A8,'Données'!$D$2:$D$822,1) -> 92.3 | F8: =IFERROR(E8/COUNTIFS('Données'!$E$2:$E$822,$A8,'Données'!$D$2:$D$822,1,'Données'!$N$2:$N$822,">0"),"") -> 9.23 | G8: =IF(D8>0,('Équipements'!$D$2-E8)/D8,"") -> 619.12143 | H8: =MAX(0,'Équipements'!$D$2-E8)/'Équipements'!$D$2 -> 0.98946347 | I8: =SUMIFS('Données'!$O$2:$O$822,'Données'!$E$2:$E$822,$A8) -> 92877.96 | J8: =COUNTIFS('Données'!$E$2:$E$822,$A8,'Données'!$Q$2:$Q$822,1) -> 3 | K8: Usure | L8: 68
A9: 10001120 | B9: Chargeuse sur pneus CAT 988 | C9: KV-MOB-988 | D9: =COUNTIFS('Données'!$E$2:$E$822,$A9,'Données'!$D$2:$D$822,1) -> 10 | E9: =SUMIFS('Données'!$N$2:$N$822,'Données'!$E$2:$E$822,$A9,'Données'!$D$2:$D$822,1) -> 81.3 | F9: =IFERROR(E9/COUNTIFS('Données'!$E$2:$E$822,$A9,'Données'!$D$2:$D$822,1,'Données'!$N$2:$N$822,">0"),"") -> 10.1625 | G9: =IF(D9>0,('Équipements'!$D$2-E9)/D9,"") -> 867.87 | H9: =MAX(0,'Équipements'!$D$2-E9)/'Équipements'!$D$2 -> 0.99071918 | I9: =SUMIFS('Données'!$O$2:$O$822,'Données'!$E$2:$E$822,$A9) -> 113619.35 | J9: =COUNTIFS('Données'!$E$2:$E$822,$A9,'Données'!$Q$2:$Q$822,1) -> 3 | K9: Hydraulique | L9: 63
A10: 10001040 | B10: Crible vibrant SC-01 | C10: KV-CRI-001 | D10: =COUNTIFS('Données'!$E$2:$E$822,$A10,'Données'!$D$2:$D$822,1) -> 12 | E10: =SUMIFS('Données'!$N$2:$N$822,'Données'!$E$2:$E$822,$A10,'Données'!$D$2:$D$822,1) -> 64.7 | F10: =IFERROR(E10/COUNTIFS('Données'!$E$2:$E$822,$A10,'Données'!$D$2:$D$822,1,'Données'!$N$2:$N$822,">0"),"") -> 7.1888889 | G10: =IF(D10>0,('Équipements'!$D$2-E10)/D10,"") -> 724.60833 | H10: =MAX(0,'Équipements'!$D$2-E10)/'Équipements'!$D$2 -> 0.99261416 | I10: =SUMIFS('Données'!$O$2:$O$822,'Données'!$E$2:$E$822,$A10) -> 61053.4 | J10: =COUNTIFS('Données'!$E$2:$E$822,$A10,'Données'!$Q$2:$Q$822,1) -> 7 | K10: Vibrations / Bruit | L10: 50
A11: 10001030 | B11: Convoyeur à bande CV-03 | C11: KV-CNV-003 | D11: =COUNTIFS('Données'!$E$2:$E$822,$A11,'Données'!$D$2:$D$822,1) -> 19 | E11: =SUMIFS('Données'!$N$2:$N$822,'Données'!$E$2:$E$822,$A11,'Données'!$D$2:$D$822,1) -> 62.36 | F11: =IFERROR(E11/COUNTIFS('Données'!$E$2:$E$822,$A11,'Données'!$D$2:$D$822,1,'Données'!$N$2:$N$822,">0"),"") -> 4.1573333 | G11: =IF(D11>0,('Équipements'!$D$2-E11)/D11,"") -> 457.77053 | H11: =MAX(0,'Équipements'!$D$2-E11)/'Équipements'!$D$2 -> 0.99288128 | I11: =SUMIFS('Données'!$O$2:$O$822,'Données'!$E$2:$E$822,$A11) -> 71223.11 | J11: =COUNTIFS('Données'!$E$2:$E$822,$A11,'Données'!$Q$2:$Q$822,1) -> 4 | K11: Bande / Convoyeur | L11: 61
A12: 10001041 | B12: Crible vibrant SC-02 | C12: KV-CRI-002 | D12: =COUNTIFS('Données'!$E$2:$E$822,$A12,'Données'!$D$2:$D$822,1) -> 6 | E12: =SUMIFS('Données'!$N$2:$N$822,'Données'!$E$2:$E$822,$A12,'Données'!$D$2:$D$822,1) -> 56.1 | F12: =IFERROR(E12/COUNTIFS('Données'!$E$2:$E$822,$A12,'Données'!$D$2:$D$822,1,'Données'!$N$2:$N$822,">0"),"") -> 9.35 | G12: =IF(D12>0,('Équipements'!$D$2-E12)/D12,"") -> 1450.65 | H12: =MAX(0,'Équipements'!$D$2-E12)/'Équipements'!$D$2 -> 0.99359589 | I12: =SUMIFS('Données'!$O$2:$O$822,'Données'!$E$2:$E$822,$A12) -> 36143.3 | J12: =COUNTIFS('Données'!$E$2:$E$822,$A12,'Données'!$Q$2:$Q$822,1) -> 4 | K12: Vibrations / Bruit | L12: 33
A13: 10001121 | B13: Tombereau CAT 777 n°12 | C13: KV-MOB-777 | D13: =COUNTIFS('Données'!$E$2:$E$822,$A13,'Données'!$D$2:$D$822,1) -> 7 | E13: =SUMIFS('Données'!$N$2:$N$822,'Données'!$E$2:$E$822,$A13,'Données'!$D$2:$D$822,1) -> 53.7 | F13: =IFERROR(E13/COUNTIFS('Données'!$E$2:$E$822,$A13,'Données'!$D$2:$D$822,1,'Données'!$N$2:$N$822,">0"),"") -> 8.95 | G13: =IF(D13>0,('Équipements'!$D$2-E13)/D13,"") -> 1243.7571 | H13: =MAX(0,'Équipements'!$D$2-E13)/'Équipements'!$D$2 -> 0.99386986 | I13: =SUMIFS('Données'!$O$2:$O$822,'Données'!$E$2:$E$822,$A13) -> 90640.36 | J13: =COUNTIFS('Données'!$E$2:$E$822,$A13,'Données'!$Q$2:$Q$822,1) -> 0 | K13: Électrique | L13: 45
A14: 10001110 | B14: Électrolyseur – redresseur RD-01 | C14: KV-ELE-001 | D14: =COUNTIFS('Données'!$E$2:$E$822,$A14,'Données'!$D$2:$D$822,1) -> 10 | E14: =SUMIFS('Données'!$N$2:$N$822,'Données'!$E$2:$E$822,$A14,'Données'!$D$2:$D$822,1) -> 46.9 | F14: =IFERROR(E14/COUNTIFS('Données'!$E$2:$E$822,$A14,'Données'!$D$2:$D$822,1,'Données'!$N$2:$N$822,">0"),"") -> 5.8625 | G14: =IF(D14>0,('Équipements'!$D$2-E14)/D14,"") -> 871.31 | H14: =MAX(0,'Équipements'!$D$2-E14)/'Équipements'!$D$2 -> 0.99464612 | I14: =SUMIFS('Données'!$O$2:$O$822,'Données'!$E$2:$E$822,$A14) -> 98941.84 | J14: =COUNTIFS('Données'!$E$2:$E$822,$A14,'Données'!$Q$2:$Q$822,1) -> 7 | K14: Électrique | L14: 49
A15: 10001070 | B15: Filtre presse FP-01 | C15: KV-FIL-001 | D15: =COUNTIFS('Données'!$E$2:$E$822,$A15,'Données'!$D$2:$D$822,1) -> 8 | E15: =SUMIFS('Données'!$N$2:$N$822,'Données'!$E$2:$E$822,$A15,'Données'!$D$2:$D$822,1) -> 46.9 | F15: =IFERROR(E15/COUNTIFS('Données'!$E$2:$E$822,$A15,'Données'!$D$2:$D$822,1,'Données'!$N$2:$N$822,">0"),"") -> 7.8166667 | G15: =IF(D15>0,('Équipements'!$D$2-E15)/D15,"") -> 1089.1375 | H15: =MAX(0,'Équipements'!$D$2-E15)/'Équipements'!$D$2 -> 0.99464612 | I15: =SUMIFS('Données'!$O$2:$O$822,'Données'!$E$2:$E$822,$A15) -> 59226.42 | J15: =COUNTIFS('Données'!$E$2:$E$822,$A15,'Données'!$Q$2:$Q$822,1) -> 1 | K15: Hydraulique | L15: 38
A16: 10001080 | B16: Compresseur d'air CP-01 | C16: KV-COM-001 | D16: =COUNTIFS('Données'!$E$2:$E$822,$A16,'Données'!$D$2:$D$822,1) -> 7 | E16: =SUMIFS('Données'!$N$2:$N$822,'Données'!$E$2:$E$822,$A16,'Données'!$D$2:$D$822,1) -> 25.9 | F16: =IFERROR(E16/COUNTIFS('Données'!$E$2:$E$822,$A16,'Données'!$D$2:$D$822,1,'Données'!$N$2:$N$822,">0"),"") -> 6.475 | G16: =IF(D16>0,('Équipements'!$D$2-E16)/D16,"") -> 1247.7286 | H16: =MAX(0,'Équipements'!$D$2-E16)/'Équipements'!$D$2 -> 0.99704338 | I16: =SUMIFS('Données'!$O$2:$O$822,'Données'!$E$2:$E$822,$A16) -> 29692.04 | J16: =COUNTIFS('Données'!$E$2:$E$822,$A16,'Données'!$Q$2:$Q$822,1) -> 5 | K16: Surchauffe | L16: 24
... A27: 10001090 | B27: Pont roulant 20 t | C27: KV-PON-001 | D27: =COUNTIFS('Données'!$E$2:$E$822,$A27,'Données'!$D$2:$D$822,1) -> 3 | E27: =SUMIFS('Données'!$N$2:$N$822,'Données'!$E$2:$E$822,$A27,'Données'!$D$2:$D$822,1) -> 4.7 | F27: =IFERROR(E27/COUNTIFS('Données'!$E$2:$E$822,$A27,'Données'!$D$2:$D$822,1,'Données'!$N$2:$N$822,">0"),"") -> 4.7 | G27: =IF(D27>0,('Équipements'!$D$2-E27)/D27,"") -> 2918.4333 | H27: =MAX(0,'Équipements'!$D$2-E27)/'Équipements'!$D$2 -> 0.99946347 | I27: =SUMIFS('Données'!$O$2:$O$822,'Données'!$E$2:$E$822,$A27) -> 20444.36 | J27: =COUNTIFS('Données'!$E$2:$E$822,$A27,'Données'!$Q$2:$Q$822,1) -> 3 | K27: Structure / Fissures | L27: 10

Sheet Modes de défaillance
A1: Modes de défaillance (Pareto des pannes)
A2: Classement issu des codes dommage SAP, des règles mots-clés et, si activée, de l'IA.
A4: Mode de défaillance | B4: Pannes | C4: Part | D4: Part cumulée | E4: Arrêt (h) | F4: Coût (USD) | G4: Équipements touchés
A5: Étanchéité / Fuites | B5: =COUNTIFS('Données'!$I$2:$I$822,$A5,'Données'!$D$2:$D$822,1) -> 30 | C5: =IFERROR(B5/SUM($B$5:$B$17),0) -> 0.14851485 | D5: =SUM($C$5:C5) -> 0.14851485 | E5: =SUMIFS('Données'!$N$2:$N$822,'Données'!$I$2:$I$822,$A5,'Données'!$D$2:$D$822,1) -> 125.1 | F5: =SUMIFS('Données'!$O$2:$O$822,'Données'!$I$2:$I$822,$A5,'Données'!$D$2:$D$822,1) -> 100146.87 | G5: 6
A6: Usure | B6: =COUNTIFS('Données'!$I$2:$I$822,$A6,'Données'!$D$2:$D$822,1) -> 25 | C6: =IFERROR(B6/SUM($B$5:$B$17),0) -> 0.12376238 | D6: =SUM($C$5:C6) -> 0.27227723 | E6: =SUMIFS('Données'!$N$2:$N$822,'Données'!$I$2:$I$822,$A6,'Données'!$D$2:$D$822,1) -> 120.6 | F6: =SUMIFS('Données'!$O$2:$O$822,'Données'!$I$2:$I$822,$A6,'Données'!$D$2:$D$822,1) -> 161112.03 | G6: 10
A7: Vibrations / Bruit | B7: =COUNTIFS('Données'!$I$2:$I$822,$A7,'Données'!$D$2:$D$822,1) -> 22 | C7: =IFERROR(B7/SUM($B$5:$B$17),0) -> 0.10891089 | D7: =SUM($C$5:C7) -> 0.38118812 | E7: =SUMIFS('Données'!$N$2:$N$822,'Données'!$I$2:$I$822,$A7,'Données'!$D$2:$D$822,1) -> 106.7 | F7: =SUMIFS('Données'!$O$2:$O$822,'Données'!$I$2:$I$822,$A7,'Données'!$D$2:$D$822,1) -> 79198.38 | G7: 5
A8: Roulements | B8: =COUNTIFS('Données'!$I$2:$I$822,$A8,'Données'!$D$2:$D$822,1) -> 21 | C8: =IFERROR(B8/SUM($B$5:$B$17),0) -> 0.1039604 | D8: =SUM($C$5:C8) -> 0.48514851 | E8: =SUMIFS('Données'!$N$2:$N$822,'Données'!$I$2:$I$822,$A8,'Données'!$D$2:$D$822,1) -> 88.68 | F8: =SUMIFS('Données'!$O$2:$O$822,'Données'!$I$2:$I$822,$A8,'Données'!$D$2:$D$822,1) -> 135926.2 | G8: 10
A9: Électrique | B9: =COUNTIFS('Données'!$I$2:$I$822,$A9,'Données'!$D$2:$D$822,1) -> 20 | C9: =IFERROR(B9/SUM($B$5:$B$17),0) -> 0.099009901 | D9: =SUM($C$5:C9) -> 0.58415842 | E9: =SUMIFS('Données'!$N$2:$N$822,'Données'!$I$2:$I$822,$A9,'Données'!$D$2:$D$822,1) -> 107.9 | F9: =SUMIFS('Données'!$O$2:$O$822,'Données'!$I$2:$I$822,$A9,'Données'!$D$2:$D$822,1) -> 124877.64 | G9: 8
A10: Surchauffe | B10: =COUNTIFS('Données'!$I$2:$I$822,$A10,'Données'!$D$2:$D$822,1) -> 18 | C10: =IFERROR(B10/SUM($B$5:$B$17),0) -> 0.089108911 | D10: =SUM($C$5:C10) -> 0.67326733 | E10: =SUMIFS('Données'!$N$2:$N$822,'Données'!$I$2:$I$822,$A10,'Données'!$D$2:$D$822,1) -> 123.1 | F10: =SUMIFS('Données'!$O$2:$O$822,'Données'!$I$2:$I$822,$A10,'Données'!$D$2:$D$822,1) -> 122336.61 | G10: 7
A11: Bande / Convoyeur | B11: =COUNTIFS('Données'!$I$2:$I$822,$A11,'Données'!$D$2:$D$822,1) -> 15 | C11: =IFERROR(B11/SUM($B$5:$B$17),0) -> 0.074257426 | D11: =SUM($C$5:C11) -> 0.74752475 | E11: =SUMIFS('Données'!$N$2:$N$822,'Données'!$I$2:$I$822,$A11,'Données'!$D$2:$D$822,1) -> 50.38 | F11: =SUMIFS('Données'!$O$2:$O$822,'Données'!$I$2:$I$822,$A11,'Données'!$D$2:$D$822,1) -> 44995.92 | G11: 3
A12: Bourrage / Obstruction | B12: =COUNTIFS('Données'!$I$2:$I$822,$A12,'Données'!$D$2:$D$822,1) -> 12 | C12: =IFERROR(B12/SUM($B$5:$B$17),0) -> 0.059405941 | D12: =SUM($C$5:C12) -> 0.80693069 | E12: =SUMIFS('Données'!$N$2:$N$822,'Données'!$I$2:$I$822,$A12,'Données'!$D$2:$D$822,1) -> 36.9 | F12: =SUMIFS('Données'!$O$2:$O$822,'Données'!$I$2:$I$822,$A12,'Données'!$D$2:$D$822,1) -> 50250.89 | G12: 4
A13: Hydraulique | B13: =COUNTIFS('Données'!$I$2:$I$822,$A13,'Données'!$D$2:$D$822,1) -> 11 | C13: =IFERROR(B13/SUM($B$5:$B$17),0) -> 0.054455446 | D13: =SUM($C$5:C13) -> 0.86138614 | E13: =SUMIFS('Données'!$N$2:$N$822,'Données'!$I$2:$I$822,$A13,'Données'!$D$2:$D$822,1) -> 69.7 | F13: =SUMIFS('Données'!$O$2:$O$822,'Données'!$I$2:$I$822,$A13,'Données'!$D$2:$D$822,1) -> 106686.7 | G13: 4
A14: Lubrification | B14: =COUNTIFS('Données'!$I$2:$I$822,$A14,'Données'!$D$2:$D$822,1) -> 10 | C14: =IFERROR(B14/SUM($B$5:$B$17),0) -> 0.04950495 | D14: =SUM($C$5:C14) -> 0.91089109 | E14: =SUMIFS('Données'!$N$2:$N$822,'Données'!$I$2:$I$822,$A14,'Données'!$D$2:$D$822,1) -> 73.9 | F14: =SUMIFS('Données'!$O$2:$O$822,'Données'!$I$2:$I$822,$A14,'Données'!$D$2:$D$822,1) -> 103129.48 | G14: 5
A15: Structure / Fissures | B15: =COUNTIFS('Données'!$I$2:$I$822,$A15,'Données'!$D$2:$D$822,1) -> 7 | C15: =IFERROR(B15/SUM($B$5:$B$17),0) -> 0.034653465 | D15: =SUM($C$5:C15) -> 0.94554455 | E15: =SUMIFS('Données'!$N$2:$N$822,'Données'!$I$2:$I$822,$A15,'Données'!$D$2:$D$822,1) -> 38.3 | F15: =SUMIFS('Données'!$O$2:$O$822,'Données'!$I$2:$I$822,$A15,'Données'!$D$2:$D$822,1) -> 43909.04 | G15: 4
A16: Autre / Non classé | B16: =COUNTIFS('Données'!$I$2:$I$822,$A16,'Données'!$D$2:$D$822,1) -> 6 | C16: =IFERROR(B16/SUM($B$5:$B$17),0) -> 0.02970297 | D16: =SUM($C$5:C16) -> 0.97524752 | E16: =SUMIFS('Données'!$N$2:$N$822,'Données'!$I$2:$I$822,$A16,'Données'!$D$2:$D$822,1) -> 17.3 | F16: =SUMIFS('Données'!$O$2:$O$822,'Données'!$I$2:$I$822,$A16,'Données'!$D$2:$D$822,1) -> 46327.49 | G16: 5
A17: Instrumentation | B17: =COUNTIFS('Données'!$I$2:$I$822,$A17,'Données'!$D$2:$D$822,1) -> 5 | C17: =IFERROR(B17/SUM($B$5:$B$17),0) -> 0.024752475 | D17: =SUM($C$5:C17) -> 1 | E17: =SUMIFS('Données'!$N$2:$N$822,'Données'!$I$2:$I$822,$A17,'Données'!$D$2:$D$822,1) -> 17.4 | F17: =SUMIFS('Données'!$O$2:$O$822,'Données'!$I$2:$I$822,$A17,'Données'!$D$2:$D$822,1) -> 24566.58 | G17: 4

Sheet Pannes récurrentes
A1: Pannes récurrentes
A2: Même équipement, même mode de défaillance, au moins 3 fois, avec plusieurs récidives à moins de 30 jours.
A4: Équipement | B4: Désignation | C4: Mode de défaillance | D4: Occurrences | E4: Récidives < 30 j | F4: Intervalle moyen (j) | G4: Arrêt (h) | H4: Coût (USD) | I4: Dernière panne | J4: Exemples de descriptions
A5: 10001020 | B5: Pompe à pulpe P-201 | C5: Étanchéité / Fuites | D5: 21 | E5: 18 | F5: 15 | G5: 76.9 | H5: 55094 | I5: 46265 | J5: fuite garniture mécanique | Fuite au niveau de la garniture | mechanical seal leak
A6: 10001030 | B6: Convoyeur à bande CV-03 | C6: Bande / Convoyeur | D6: 12 | E6: 7 | F6: 31 | G6: 36.9 | H6: 35466.48 | I6: 46265 | J6: Bande déchirée | RAS après contrôle | racleur usé bande sale
A7: 10001040 | B7: Crible vibrant SC-01 | C7: Vibrations / Bruit | D7: 7 | E7: 2 | F7: 45.5 | G7: 33 | H7: 22021.75 | I7: 46254 | J7: machine fait du bruit | bruit anormal pompe | excessive vibration
A8: 10001110 | B8: Électrolyseur – redresseur RD-01 | C8: Électrique | D8: 6 | E8: 3 | F8: 40.4 | G8: 26.7 | H8: 43640.66 | I8: 46256 | J8: disjoncteur déclenché | Défaut moteur électrique | Contacteur HS
A9: 10001020 | B9: Pompe à pulpe P-201 | C9: Vibrations / Bruit | D9: 5 | E9: 2 | F9: 59 | G9: 6.3 | H9: 8904.41 | I9: 46141 | J9: vibrations anormales | claquement au démarrage | machine fait du bruit
A10: 10001041 | B10: Crible vibrant SC-02 | C10: Vibrations / Bruit | D10: 4 | E10: 2 | F10: 69 | G10: 43.2 | H10: 24146.59 | I10: 46226 | J10: vibrations anormales | bruit anormal pompe | claquement au démarrage
A11: 10001010 | B11: Broyeur à boulets n°1 | C11: Lubrification | D11: 4 | E11: 2 | F11: 65 | G11: 40.2 | H11: 73932.55 | I11: 46256 | J11: niveau huile bas réducteur | pompe graissage HS | défaut lubrification
A12: 10001110 | B12: Électrolyseur – redresseur RD-01 | C12: Surchauffe | D12: 4 | E12: 2 | F12: 85.7 | G12: 20.2 | H12: 26879.4 | I12: 46243 | J12: Alarme température huile | température élevée réducteur | échauffement palier
A13: 10001021 | B13: Pompe à pulpe P-202 | C13: Étanchéité / Fuites | D13: 4 | E13: 2 | F13: 40.3 | G13: 6.9 | H13: 14142.57 | I13: 46151 | J13: fuite pulpe presse-étoupe | joint HS fuite eau | Fuite importante côté refoulement

Sheet Tendance
A1: Tendance mensuelle
A3: Mois | B3: Ordres | C3: Pannes | D3: Ordres planifiés | E3: Part planifiée | F3: Arrêt (h) | G3: Coût (USD)
A4: 45901 | B4: 60 | C4: 9 | D4: 51 | E4: =IFERROR(D4/B4,0) -> 0.85 | F4: 41.2 | G4: 89269.3
A5: 45931 | B5: 68 | C5: 13 | D5: 55 | E5: =IFERROR(D5/B5,0) -> 0.80882353 | F5: 41.18 | G5: 107225.19
A6: 45962 | B6: 62 | C6: 16 | D6: 46 | E6: =IFERROR(D6/B6,0) -> 0.74193548 | F6: 53.5 | G6: 89842.66
A7: 45992 | B7: 73 | C7: 17 | D7: 56 | E7: =IFERROR(D7/B7,0) -> 0.76712329 | F7: 73.6 | G7: 123397.24
A8: 46023 | B8: 71 | C8: 18 | D8: 53 | E8: =IFERROR(D8/B8,0) -> 0.74647887 | F8: 123.4 | G8: 143026.68
A9: 46054 | B9: 72 | C9: 24 | D9: 48 | E9: =IFERROR(D9/B9,0) -> 0.66666667 | F9: 112.5 | G9: 190635.75
A10: 46082 | B10: 75 | C10: 17 | D10: 58 | E10: =IFERROR(D10/B10,0) -> 0.77333333 | F10: 69.1 | G10: 148791.03
A11: 46113 | B11: 57 | C11: 13 | D11: 44 | E11: =IFERROR(D11/B11,0) -> 0.77192982 | F11: 52.9 | G11: 79868.15
A12: 46143 | B12: 69 | C12: 15 | D12: 54 | E12: =IFERROR(D12/B12,0) -> 0.7826087 | F12: 65.98 | G12: 84256.24
A13: 46174 | B13: 66 | C13: 21 | D13: 45 | E13: =IFERROR(D13/B13,0) -> 0.68181818 | F13: 103.5 | G13: 132681.57
A14: 46204 | B14: 77 | C14: 20 | D14: 57 | E14: =IFERROR(D14/B14,0) -> 0.74025974 | F14: 100.5 | G14: 113883.88
A15: 46235 | B15: 71 | C15: 19 | D15: 52 | E15: =IFERROR(D15/B15,0) -> 0.73239437 | F15: 138.6 | G15: 151449.03

Sheet Backlog
A1: Ordres ouverts (backlog)
A2: Situation au 31/08/2026 (dernier jour de l'export). En retard = date de début de base (IW39 « Bsc start ») dépassée.
A4: Ancienneté | B4: Ordres | D4: Poste de travail principal | E4: Ouverts | F4: En retard | G4: Priorité 1-2 | H4: Retard max (j)
A5: 0–7 j | B5: 22 | D5: MECA-01 | E5: 18 | F5: 14 | G5: 15 | H5: 219
A6: 8–30 j | B6: 21 | D6: MECA-MAN | E6: 17 | F6: 11 | G6: 4 | H6: 327
A7: 31–90 j | B7: 13 | D7: MECA-HYD | E7: 13 | F7: 7 | G7: 5 | H7: 164
A8: > 90 j | B8: 18 | D8: MECA-UTI | E8: 9 | F8: 6 | G8: 3 | H8: 309
D9: ELEC-01 | E9: 7 | F9: 6 | G9: 3 | H9: 224
D10: MECA-BRO | E10: 5 | F10: 4 | G10: 1 | H10: 336
D11: MECA-CON | E11: 3 | F11: 3 | G11: 2 | H11: 303
D12: MECA-MOB | E12: 2 | F12: 1 | G12: 1 | H12: 163
A15: Ordre | B15: Type | C15: Poste de travail | D15: Équipement | E15: Désignation | F15: Description | G15: Priorité | H15: Statut | I15: Créé le | J15: Début de base | K15: Retard (j) | L15: Âge (j)
A16: 4000038 | B16: PM02 | C16: MECA-BRO | D16: 10001011 | E16: Broyeur à boulets n°2 | F16: Inspection vibratoire | G16: 3 | H16: REL | I16: 45919 | J16: 45929 | K16: 336 | L16: 347
A17: 4000056 | B17: PM02 | C17: MECA-MAN | D17: 10001030 | E17: Convoyeur à bande CV-03 | F17: Analyse d'huile trimestrielle | G17: 3 | H17: REL | I17: 45928 | J17: 45938 | K17: 327 | L17: 338
A18: 4000097 | B18: PM03 | C18: MECA-UTI | D18: 10001081 | E18: Compresseur d'air CP-02 | F18: Inspection thermographique | G18: 3 | H18: REL | I18: 45946 | J18: 45956 | K18: 309 | L18: 320
A19: 4000107 | B19: PM02 | C19: MECA-CON | D19: 10001002 | E19: Concasseur secondaire à cône | F19: Graissage hebdomadaire | G19: 2 | H19: REL | I19: 45952 | J19: 45962 | K19: 303 | L19: 314
A20: 4000141 | B20: PM02 | C20: MECA-BRO | D20: 10001011 | E20: Broyeur à boulets n°2 | F20: Analyse d'huile trimestrielle | G20: 3 | H20: REL | I20: 45967 | J20: 45977 | K20: 288 | L20: 299
A21: 4000282 | B21: PM02 | C21: ELEC-01 | D21: 10001110 | E21: Électrolyseur – redresseur RD-01 | F21: PM 500h - inspection mensuelle | G21: 3 | H21: REL | I21: 46031 | J21: 46041 | K21: 224 | L21: 235
A22: 4000316 | B22: PM04 | C22: MECA-01 | D22: 10001021 | E22: Pompe à pulpe P-202 | F22: joint HS fuite eau | G22: 1 | H22: REL | I22: 46046 | J22: 46046 | K22: 219 | L22: 220
A23: 4000306 | B23: PM02 | C23: MECA-MAN | D23: 10001040 | E23: Crible vibrant SC-01 | F23: Contrôle hebdomadaire bande | G23: 3 | H23: REL | I23: 46041 | J23: 46051 | K23: 214 | L23: 225
A24: 4000365 | B24: PM04 | C24: ELEC-01 | D24: 10001110 | E24: Électrolyseur – redresseur RD-01 | F24: Défaut moteur électrique | G24: 1 | H24: REL | I24: 46063 | J24: 46065 | K24: 200 | L24: 203
A25: 4000358 | B25: PM03 | C25: MECA-MAN | D25: 10001031 | E25: Convoyeur à bande CV-04 | F25: Ronde d'inspection | G25: 2 | H25: REL | I25: 46061 | J25: 46071 | K25: 194 | L25: 205
A26: 4000376 | B26: PM01 | C26: MECA-01 | D26: 10001011 | E26: Broyeur à boulets n°2 | F26: niveau huile bas réducteur | G26: 2 | H26: REL | I26: 46071 | J26: 46074 | K26: 191 | L26: 195
A27: 4000426 | B27: PM02 | C27: MECA-MAN | D27: 10001041 | E27: Crible vibrant SC-02 | F27: Graissage hebdomadaire | G27: 3 | H27: REL | I27: 46090 | J27: 46100 | K27: 165 | L27: 176
... A89: 4000817 | B89: PM02 | C89: MECA-HYD | D89: 10001050 | E89: Cellule de flottation FL-05 | F89: Graissage hebdomadaire | G89: 3 | H89: CRTD | I89: 46265 | J89: 46275 | K89: 0 | L89: 1

Sheet Qualité données
A1: Qualité des données
A2: Des données incomplètes produisent des analyses fausses mais convaincantes : à lire avant les conclusions.
A4: Score de qualité (0-100) | B4: 80
A6: Contrôle | B6: Nombre
A7: Ordres lus | B7: 822
A8: Ordres en double (retirés de l'analyse) | B8: 1
A9: Ordres sans date de création | B9: 0
A10: Pannes sans code dommage SAP | B10: 128
A11: Pannes sans date de fin de panne | B11: 3
A12: Durées négatives (fin avant début, ignorées) | B12: 1
A13: Pannes non classées (texte trop vague) | B13: 6

Sheet Données
A1: Ordre | B1: Type d'ordre | C1: Nature | D1: Panne (1/0) | E1: Équipement | F1: Désignation | G1: Poste technique | H1: Description | I1: Mode de défaillance | J1: Source classification | K1: Date de création | L1: Début panne | M1: Fin panne | N1: Arrêt (h) | O1: Coût (USD) | P1: Statut | Q1: Ouvert (1/0) | R1: Priorité | S1: Code dommage
A2: 4000000 | B2: PM02 | C2: Préventif | D2: 0 | E2: 10001031 | F2: Convoyeur à bande CV-04 | G2: KV-CNV-004 | H2: Analyse d'huile trimestrielle | J2: Ordre planifié | K2: 45901 | N2: 0 | O2: 473.37 | P2: TECO | Q2: 0 | R2: 3
A3: 4000001 | B3: PM02 | C3: Préventif | D3: 0 | E3: 10001041 | F3: Crible vibrant SC-02 | G3: KV-CRI-002 | H3: Visite systématique | J3: Ordre planifié | K3: 45901 | N3: 0 | O3: 509.69 | P3: TECO | Q3: 0 | R3: 2
A4: 4000002 | B4: PM03 | C4: Inspection | D4: 0 | E4: 10001090 | F4: Pont roulant 20 t | G4: KV-PON-001 | H4: Ronde d'inspection | J4: Ordre planifié | K4: 45901 | N4: 0 | O4: 120 | P4: TECO | Q4: 0 | R4: 4
A5: 4000003 | B5: PM02 | C5: Préventif | D5: 0 | E5: 10001002 | F5: Concasseur secondaire à cône | G5: KV-CON-020 | H5: Graissage hebdomadaire | J5: Ordre planifié | K5: 45902 | N5: 0 | O5: 799.72 | P5: CLSD | Q5: 0 | R5: 2
A6: 4000004 | B6: PM03 | C6: Inspection | D6: 0 | E6: 10001021 | F6: Pompe à pulpe P-202 | G6: KV-POM-202 | H6: Contrôle ultrasons | J6: Ordre planifié | K6: 45902 | N6: 0 | O6: 80 | P6: TECO | Q6: 0 | R6: 2
A7: 4000005 | B7: PM03 | C7: Inspection | D7: 0 | E7: 10001040 | F7: Crible vibrant SC-01 | G7: KV-CRI-001 | H7: Ronde d'inspection | J7: Ordre planifié | K7: 45902 | N7: 0 | O7: 160 | P7: CLSD | Q7: 0 | R7: 4
A8: 4000006 | B8: PM03 | C8: Inspection | D8: 0 | E8: 10001060 | F8: Épaississeur TH-01 | G8: KV-EPA-001 | H8: Ronde d'inspection | J8: Ordre planifié | K8: 45902 | N8: 0 | O8: 240 | P8: CLSD | Q8: 0 | R8: 2
A9: 4000007 | B9: PM02 | C9: Préventif | D9: 0 | E9: 10001011 | F9: Broyeur à boulets n°2 | G9: KV-BRO-020 | H9: PM 500h - inspection mensuelle | J9: Ordre planifié | K9: 45903 | N9: 0 | O9: 1363.1 | P9: CLSD | Q9: 0 | R9: 4
A10: 4000008 | B10: PM02 | C10: Préventif | D10: 0 | E10: 10001040 | F10: Crible vibrant SC-01 | G10: KV-CRI-001 | H10: Remplacement filtres huile - préventif | J10: Ordre planifié | K10: 45905 | N10: 0 | O10: 529.96 | P10: CLSD | Q10: 0 | R10: 2
A11: 4000009 | B11: PM02 | C11: Préventif | D11: 0 | E11: 10001110 | F11: Électrolyseur – redresseur RD-01 | G11: KV-ELE-001 | H11: Remplacement filtres huile - préventif | J11: Ordre planifié | K11: 45905 | N11: 0 | O11: 869.34 | P11: CLSD | Q11: 0 | R11: 2
A12: 4000010 | B12: PM03 | C12: Inspection | D12: 0 | E12: 10001002 | F12: Concasseur secondaire à cône | G12: KV-CON-020 | H12: Ronde d'inspection | J12: Ordre planifié | K12: 45905 | N12: 0 | O12: 260 | P12: TECO | Q12: 0 | R12: 3
A13: 4000011 | B13: PM01 | C13: Correctif | D13: 1 | E13: 10001020 | F13: Pompe à pulpe P-201 | G13: KV-POM-201 | H13: vibrations anormales | I13: Vibrations / Bruit | J13: Code SAP | K13: 45905 | L13: 45905.744 | M13: 45905.552 | N13: 0 | O13: 1350.24 | P13: CLSD | Q13: 0 | R13: 2 | S13: VIBR
A14: 4000012 | B14: PM02 | C14: Préventif | D14: 0 | E14: 10001030 | F14: Convoyeur à bande CV-03 | G14: KV-CNV-003 | H14: Graissage hebdomadaire | J14: Ordre planifié | K14: 45906 | N14: 0 | O14: 266.19 | P14: TECO | Q14: 0 | R14: 4
A15: 4000013 | B15: PM03 | C15: Inspection | D15: 0 | E15: 10001001 | F15: Concasseur primaire giratoire | G15: KV-CON-010 | H15: Inspection thermographique | J15: Ordre planifié | K15: 45906 | N15: 0 | O15: 360 | P15: TECO | Q15: 0 | R15: 3
A16: 4000014 | B16: PM03 | C16: Inspection | D16: 0 | E16: 10001051 | F16: Cellule de flottation FL-06 | G16: KV-FLO-006 | H16: Ronde d'inspection | J16: Ordre planifié | K16: 45906 | N16: 0 | O16: 100 | P16: TECO | Q16: 0 | R16: 2
A17: 4000015 | B17: PM03 | C17: Inspection | D17: 0 | E17: 10001080 | F17: Compresseur d'air CP-01 | G17: KV-COM-001 | H17: Inspection thermographique | J17: Ordre planifié | K17: 45906 | N17: 0 | O17: 140 | P17: CLSD | Q17: 0 | R17: 2
A18: 4000016 | B18: PM02 | C18: Préventif | D18: 0 | E18: 10001020 | F18: Pompe à pulpe P-201 | G18: KV-POM-201 | H18: Remplacement filtres huile - préventif | J18: Ordre planifié | K18: 45907 | N18: 0 | O18: 280.96 | P18: CLSD | Q18: 0 | R18: 3
A19: 4000017 | B19: PM03 | C19: Inspection | D19: 0 | E19: 10001020 | F19: Pompe à pulpe P-201 | G19: KV-POM-201 | H19: Inspection thermographique | J19: Ordre planifié | K19: 45907 | N19: 0 | O19: 88 | P19: TECO | Q19: 0 | R19: 2
A20: 4000018 | B20: PM02 | C20: Préventif | D20: 0 | E20: 10001010 | F20: Broyeur à boulets n°1 | G20: KV-BRO-010 | H20: Graissage hebdomadaire | J20: Ordre planifié | K20: 45908 | N20: 0 | O20: 2068.73 | P20: TECO | Q20: 0 | R20: 3
A21: 4000019 | B21: PM02 | C21: Préventif | D21: 0 | E21: 10001121 | F21: Tombereau CAT 777 n°12 | G21: KV-MOB-777 | H21: Graissage hebdomadaire | J21: Ordre planifié | K21: 45909 | N21: 0 | O21: 1170.08 | P21: CLSD | Q21: 0 | R21: 4
A22: 4000020 | B22: PM02 | C22: Préventif | D22: 0 | E22: 10001032 | F22: Convoyeur d'alimentation CV-01 | G22: KV-CNV-001 | H22: PM 500h - inspection mensuelle | J22: Ordre planifié | K22: 45910 | N22: 0 | O22: 345.22 | P22: CLSD | Q22: 0 | R22: 2
A23: 4000021 | B23: PM02 | C23: Préventif | D23: 0 | E23: 10001070 | F23: Filtre presse FP-01 | G23: KV-FIL-001 | H23: Graissage hebdomadaire | J23: Ordre planifié | K23: 45910 | N23: 0 | O23: 448.08 | P23: CLSD | Q23: 0 | R23: 3
A24: 4000022 | B24: PM02 | C24: Préventif | D24: 0 | E24: 10001021 | F24: Pompe à pulpe P-202 | G24: KV-POM-202 | H24: Graissage hebdomadaire | J24: Ordre planifié | K24: 45911 | N24: 0 | O24: 297.34 | P24: TECO | Q24: 0 | R24: 4
A25: 4000023 | B25: PM02 | C25: Préventif | D25: 0 | E25: 10001051 | F25: Cellule de flottation FL-06 | G25: KV-FLO-006 | H25: Remplacement filtres huile - préventif | J25: Ordre planifié | K25: 45911 | N25: 0 | O25: 302.82 | P25: CLSD | Q25: 0 | R25: 3
... A32: 4000030 | B32: PM02 | C32: Préventif | D32: 0 | E32: 10001090 | F32: Pont roulant 20 t | G32: KV-PON-001 | H32: Remplacement filtres huile - préventif | J32: Ordre planifié | K32: 45916 | N32: 0 | O32: 377.03 | P32: CLSD | Q32: 0 | R32: 3
A33: 4000031 | B33: PM01 | C33: Correctif | D33: 1 | E33: 10001001 | F33: Concasseur primaire giratoire | G33: KV-CON-010 | H33: Jeu excessif au palier | I33: Roulements | J33: Règles mots-clés | K33: 45916 | L33: 45916.372 | M33: 45916.522 | N33: 0 | O33: 6530.54 | P33: CLSD | Q33: 0 | R33: 3
A34: 4000032 | B34: PM03 | C34: Inspection | D34: 0 | E34: 10001081 | F34: Compresseur d'air CP-02 | G34: KV-COM-002 | H34: Ronde d'inspection | J34: Ordre planifié | K34: 45916 | N34: 0 | O34: 120 | P34: TECO | Q34: 0 | R34: 3
A35: 4000033 | B35: PM01 | C35: Correctif | D35: 1 | E35: 10001120 | F35: Chargeuse sur pneus CAT 988 | G35: KV-MOB-988 | H35: hydraulic hose burst | I35: Hydraulique | J35: Règles mots-clés | K35: 45916 | L35: 45916.977 | M35: 45917.044 | N35: 1.6 | O35: 25661.23 | P35: CLSD | Q35: 0 | R35: 3
A36: 4000034 | B36: PM02 | C36: Préventif | D36: 0 | E36: 10001050 | F36: Cellule de flottation FL-05 | G36: KV-FLO-005 | H36: Remplacement filtres huile - préventif | J36: Ordre planifié | K36: 45917 | N36: 0 | O36: 321.72 | P36: TECO | Q36: 0 | R36: 2
A37: 4000035 | B37: PM02 | C37: Préventif | D37: 0 | E37: 10001081 | F37: Compresseur d'air CP-02 | G37: KV-COM-002 | H37: Remplacement filtres huile - préventif | J37: Ordre planifié | K37: 45917 | N37: 0 | O37: 259.85 | P37: CLSD | Q37: 0 | R37: 3
A38: 4000036 | B38: PM03 | C38: Inspection | D38: 0 | E38: 10001121 | F38: Tombereau CAT 777 n°12 | G38: KV-MOB-777 | H38: Contrôle ultrasons | J38: Ordre planifié | K38: 45917 | N38: 0 | O38: 320 | P38: TECO | Q38: 0 | R38: 4
A39: 4000037 | B39: PM02 | C39: Préventif | D39: 0 | E39: 10001031 | F39: Convoyeur à bande CV-04 | G39: KV-CNV-004 | H39: Visite systématique | J39: Ordre planifié | K39: 45918 | N39: 0 | O39: 601.16 | P39: CLSD | Q39: 0 | R39: 4
A40: 4000038 | B40: PM02 | C40: Préventif | D40: 0 | E40: 10001011 | F40: Broyeur à boulets n°2 | G40: KV-BRO-020 | H40: Inspection vibratoire | J40: Ordre planifié | K40: 45919 | N40: 0 | O40: 1083.56 | P40: REL | Q40: 1 | R40: 3
A41: 4000039 | B41: PM02 | C41: Préventif | D41: 0 | E41: 10001110 | F41: Électrolyseur – redresseur RD-01 | G41: KV-ELE-001 | H41: Inspection vibratoire | J41: Ordre planifié | K41: 45919 | N41: 0 | O41: 1102.68 | P41: CLSD | Q41: 0 | R41: 2
A42: 4000040 | B42: PM02 | C42: Préventif | D42: 0 | E42: 10001120 | F42: Chargeuse sur pneus CAT 988 | G42: KV-MOB-988 | H42: PM 500h - inspection mensuelle | J42: Ordre planifié | K42: 45919 | N42: 0 | O42: 1070.84 | P42: TECO | Q42: 0 | R42: 3
A43: 4000041 | B43: PM01 | C43: Correctif | D43: 1 | E43: 10001002 | F43: Concasseur secondaire à cône | G43: KV-CON-020 | H43: flexible hydraulique éclaté | I43: Hydraulique | J43: Règles mots-clés | K43: 45919 | L43: 45919.694 | M43: 45920.065 | N43: 8.9 | O43: 3944.34 | P43: CLSD | Q43: 0 | R43: 2
A44: 4000042 | B44: PM01 | C44: Correctif | D44: 1 | E44: 10001001 | F44: Concasseur primaire giratoire | G44: KV-CON-010 | H44: liner wear | I44: Usure | J44: Code SAP | K44: 45920 | L44: 45920.074 | M44: 45920.716 | N44: 15.4 | O44: 6049.06 | P44: CLSD | Q44: 0 | R44: 3 | S44: USUR
A45: 4000043 | B45: PM02 | C45: Préventif | D45: 0 | E45: 10001022 | F45: Pompe d'eau de procédé P-301 | G45: KV-POM-301 | H45: Analyse d'huile trimestrielle | J45: Ordre planifié | K45: 45920 | N45: 0 | O45: 152.66 | P45: CLSD | Q45: 0 | R45: 3
A46: 4000044 | B46: PM02 | C46: Préventif | D46: 0 | E46: 10001080 | F46: Compresseur d'air CP-01 | G46: KV-COM-001 | H46: Graissage hebdomadaire | J46: Ordre planifié | K46: 45920 | N46: 0 | O46: 397.94 | P46: CLSD | Q46: 0 | R46: 2
...

Sheet Méthode
A1: Méthode et définitions
A3: Panne | B3: Ordre de type correctif ou urgence (par défaut PM01 / PM04, paramétrable).
A4: Arrêt (h) | B4: Fin panne − début panne, pour les ordres marqués « Arrêt machine ». Les durées négatives sont ignorées.
A5: MTTR | B5: Mean Time To Repair : heures d'arrêt / nombre de pannes ayant causé un arrêt.
A6: MTBF | B6: Mean Time Between Failures : (durée de la période − heures d'arrêt) / nombre de pannes.
A7: Disponibilité | B7: (Durée de la période − heures d'arrêt) / durée de la période.
A8: Part planifiée | B8: Ordres préventifs + inspections / total des ordres. Référence courante : ~80 %.
A9: Criticité | B9: Moyenne des parts de l'équipement dans le total des arrêts, des pannes et des coûts ; 100 = équipement le plus pénalisant.
A10: Ordre en retard | B10: Ordre ouvert dont la date de début de base (IW39 « Bsc start date ») est dépassée au dernier jour de l'export.
A11: Panne récurrente | B11: Même équipement et même mode de défaillance, au moins 3 occurrences, dont au moins 2 récidives à moins de 30 jours.
A12: Classification | B12: 1) code dommage SAP s'il est reconnu ; 2) règles mots-clés FR/EN sur le texte libre ; 3) IA (Claude ou modèle OpenRouter) pour les textes restants, si activée.
A13: Rôle de l'IA | B13: L'IA ne calcule aucun indicateur. Elle classe les textes et rédige l'analyse à partir des chiffres calculés ici. Les recommandations doivent être validées par un ingénieur.
A14: Source | B14: exemple_export_sap_pm.xlsx — période du 01/09/2025 au 31/08/2026.
